<!-- simple_arm.urdf -->
<robot name="simple_arm">
  <!-- Base link -->
  <link name="base_link">
    <visual>
      <geometry>
        <box size="0.1 0.1 0.1"/>
      </geometry>
      <material name="gray">
        <color rgba="0.5 0.5 0.5 1"/>
      </material>
    </visual>
  </link>

  <!-- First link -->
  <link name="link1">
    <visual>
      <geometry>
        <cylinder radius="0.02" length="0.3"/>
      </geometry>
      <material name="blue">
        <color rgba="0 0 1 1"/>
      </material>
    </visual>
  </link>

  <!-- First joint -->
  <joint name="joint1" type="revolute">
    <parent link="base_link"/>
    <child link="link1"/>
    <origin xyz="0 0 0.05" rpy="0 0 0"/>
    <axis xyz="0 0 1"/>
    <limit lower="-3.14" upper="3.14" effort="10" velocity="1"/>
  </joint>

  <!-- Second link -->
  <link name="link2">
    <visual>
      <geometry>
        <cylinder radius="0.02" length="0.3"/>
      </geometry>
      <material name="red">
        <color rgba="1 0 0 1"/>
      </material>
    </visual>
  </link>

  <!-- Second joint -->
  <joint name="joint2" type="revolute">
    <parent link="link1"/>
    <child link="link2"/>
    <origin xyz="0 0 0.3" rpy="0 0 0"/>
    <axis xyz="0 0 1"/>
    <limit lower="-3.14" upper="3.14" effort="10" velocity="1"/>
  </joint>
</robot>